Cause exception while process update id=474060513 by bot id=8185190653
ValueError: parameters are of unsupported type
Traceback (most recent call last):
  File "/usr/local/lib/python3.10/dist-packages/aiogram/dispatcher/dispatcher.py", line 309, in _process_update
    response = await self.feed_update(bot, update, **kwargs)
  File "/usr/local/lib/python3.10/dist-packages/aiogram/dispatcher/dispatcher.py", line 158, in feed_update
    response = await self.update.wrap_outer_middleware(
  File "/usr/local/lib/python3.10/dist-packages/aiogram/dispatcher/middlewares/error.py", line 25, in __call__
    return await handler(event, data)
  File "/usr/local/lib/python3.10/dist-packages/aiogram/dispatcher/middlewares/user_context.py", line 49, in __call__
    return await handler(event, data)
  File "/usr/local/lib/python3.10/dist-packages/aiogram/fsm/middleware.py", line 42, in __call__
    return await handler(event, data)
  File "/usr/local/lib/python3.10/dist-packages/aiogram/dispatcher/event/telegram.py", line 121, in trigger
    return await wrapped_inner(event, kwargs)
  File "/usr/local/lib/python3.10/dist-packages/aiogram/dispatcher/event/handler.py", line 43, in call
    return await wrapped()
  File "/usr/local/lib/python3.10/dist-packages/aiogram/dispatcher/dispatcher.py", line 276, in _listen_update
    return await self.propagate_event(update_type=update_type, event=event, **kwargs)
  File "/usr/local/lib/python3.10/dist-packages/aiogram/dispatcher/router.py", line 142, in propagate_event
    return await observer.wrap_outer_middleware(_wrapped, event=event, data=kwargs)
  File "/usr/local/lib/python3.10/dist-packages/aiogram/dispatcher/router.py", line 137, in _wrapped
    return await self._propagate_event(
  File "/usr/local/lib/python3.10/dist-packages/aiogram/dispatcher/router.py", line 170, in _propagate_event
    response = await router.propagate_event(update_type=update_type, event=event, **kwargs)
  File "/usr/local/lib/python3.10/dist-packages/aiogram/dispatcher/router.py", line 142, in propagate_event
    return await observer.wrap_outer_middleware(_wrapped, event=event, data=kwargs)
  File "/usr/local/lib/python3.10/dist-packages/aiogram/dispatcher/router.py", line 137, in _wrapped
    return await self._propagate_event(
  File "/usr/local/lib/python3.10/dist-packages/aiogram/dispatcher/router.py", line 162, in _propagate_event
    response = await observer.trigger(event, **kwargs)
  File "/usr/local/lib/python3.10/dist-packages/aiogram/dispatcher/event/telegram.py", line 121, in trigger
    return await wrapped_inner(event, kwargs)
  File "/usr/local/lib/python3.10/dist-packages/aiogram/dispatcher/event/handler.py", line 43, in call
    return await wrapped()
  File "/root/ilyasdev/MasterTask/app/handlers.py", line 301, in my_code_callback_handler
    data = await sql.get_user_friend_statistics_sql(callback.from_user.id)
  File "/root/ilyasdev/MasterTask/app/database/sqlite_db.py", line 122, in get_user_friend_statistics_sql
    return cur.execute("SELECT * FROM friend_statistics WHERE id = ?", (tg_id)).fetchone()
ValueError: parameters are of unsupported type
Received SIGTERM signal
